Traceback (most recent call last):
  File "/apps/system/easybuild/software/Anaconda3/2022.05/lib/python3.9/site-packages/requests/adapters.py", line 440, in send
    resp = conn.urlopen(
  File "/apps/system/easybuild/software/Anaconda3/2022.05/lib/python3.9/site-packages/urllib3/connectionpool.py", line 876, in urlopen
    return self.urlopen(
  File "/apps/system/easybuild/software/Anaconda3/2022.05/lib/python3.9/site-packages/urllib3/connectionpool.py", line 876, in urlopen
    return self.urlopen(
  File "/apps/system/easybuild/software/Anaconda3/2022.05/lib/python3.9/site-packages/urllib3/connectionpool.py", line 876, in urlopen
    return self.urlopen(
  [Previous line repeated 7 more times]
  File "/apps/system/easybuild/software/Anaconda3/2022.05/lib/python3.9/site-packages/urllib3/connectionpool.py", line 866, in urlopen
    retries = retries.increment(method, url, response=response, _pool=self)
  File "/apps/system/easybuild/software/Anaconda3/2022.05/lib/python3.9/site-packages/urllib3/util/retry.py", line 592, in increment
    raise MaxRetryError(_pool, url, error or ResponseError(cause))
urllib3.exceptions.MaxRetryError: HTTPSConnectionPool(host='nda.nih.gov', port=443): Max retries exceeded with url: /api/package/1232950 (Caused by ResponseError('too many 503 error responses'))

During handling of the above exception, another exception occurred:

Traceback (most recent call last):
  File "/home/kebl7678/.local/bin/downloadcmd", line 8, in <module>
    sys.exit(main())
  File "/home/kebl7678/.local/lib/python3.9/site-packages/NDATools/clientscripts/downloadcmd.py", line 182, in main
    s3Download.start()
  File "/home/kebl7678/.local/lib/python3.9/site-packages/NDATools/Download.py", line 198, in start
    package_resource = self.get_package_info()
  File "/home/kebl7678/.local/lib/python3.9/site-packages/NDATools/Download.py", line 1010, in get_package_info
    tmp = get_request(url, auth=self.auth, deserialize_handler=DeserializeHandler.none)
  File "/home/kebl7678/.local/lib/python3.9/site-packages/NDATools/Utils.py", line 304, in get_request
    return _send_prepared_request(req.prepare(), timeout=timeout, deserialize_handler=deserialize_handler,
  File "/home/kebl7678/.local/lib/python3.9/site-packages/NDATools/Utils.py", line 266, in _retry
    tmp = func(*args, **kwargs)
  File "/home/kebl7678/.local/lib/python3.9/site-packages/NDATools/Utils.py", line 293, in _send_prepared_request
    tmp = session.send(prepped, timeout=timeout)
  File "/apps/system/easybuild/software/Anaconda3/2022.05/lib/python3.9/site-packages/requests/sessions.py", line 645, in send
    r = adapter.send(request, **kwargs)
  File "/apps/system/easybuild/software/Anaconda3/2022.05/lib/python3.9/site-packages/requests/adapters.py", line 510, in send
    raise RetryError(e, request=request)
requests.exceptions.RetryError: HTTPSConnectionPool(host='nda.nih.gov', port=443): Max retries exceeded with url: /api/package/1232950 (Caused by ResponseError('too many 503 error responses'))
